Workbook

Sheet Home

Sheet Total
B2: Staff & Vendors | E2: Dr & Cr Total | I2: Store Data | M2: LB Data | Q2: Salaries Total
B3: S.Naeem | C3: =SUM(Staff!B33) -> #REF! | E3: Purchase Price Med (St) | F3: =SUM(Data!D33) -> #REF! | I3: Sale Price (TP) Med (St) | J3: - | K3: Purchase Price Med (St) | M3: LB inc | N3: - | O3: LB Exp | Q3: =SUM(C4,C11,C12,C13,C16,C17) -> #REF!
B4: Ammar | C4: =SUM(Staff!C33) -> #REF! | E4: Sale Price (TP) Med (St) | F4: =SUM(Data!E33) -> #REF! | I4: =SUM(F4) -> #REF! | J4: - | K4: =SUM(F3) -> #REF! | M4: =SUM(F10) -> #REF! | N4: - | O4: =SUM(F11) -> #REF! | Q4: Clinic Exp
B5: Noman | C5: =SUM(Staff!D33) -> #REF! | E5: Home Exp | F5: =SUM(Data!F33) -> #REF! | I5: Store Profit | K5: =F4-F3 -> #REF! | M5: =F10-F11 -> #REF! | Q5: =SUM(F6) -> #REF!
B6: Naveed | C6: =SUM(Staff!E33) -> #REF! | E6: Clinic Exp | F6: =SUM(Data!G33) -> #REF!
B7: Baig sb | C7: =SUM(Staff!F33) -> #REF! | E7: US | F7: =SUM(Data!H33) -> #REF! | I7: Prev Month Stock TP | J7: + | K7: Purchase This Month TP | M7: Disp Data | Q7: Clinic Gross
B8: Bilal MR | C8: =SUM(Staff!G33) -> #REF! | E8: Disp (Clinic) inc | F8: =SUM(Data!I33) -> #REF! | J8: + | K8: =SUM(F4) -> #REF! | M8: Disp inc | N8: - | O8: Disp Purch | Q8: Clinic Inc | R8: - | S8: Total Exp
B9: Komal | C9: =SUM(Staff!H33) -> #REF! | E9: St Sales | F9: =SUM(Data!J33) -> #REF! | I9: =SUM(I8,K8) -> #REF! | M9: =SUM(F8) -> #REF! | N9: - | O9: =SUM(F15) -> #REF! | Q9: =SUM(M10) -> #REF! | R9: - | S9: =SUM(Q3,Q5) -> #REF!
B10: Amir Shah | C10: =SUM(Staff!I33) -> #REF! | E10: LB inc | F10: =SUM(Data!K33) -> #REF! | M10: =F8-F15 -> #REF! | Q10: =Q9-S9 -> #REF!
B11: Adnan | C11: =SUM(Staff!J33) -> #REF! | E11: LB Exp | F11: =SUM(Data!L33) -> #REF! | I11: St Sale This Month | J11: + | K11: Present Month Stock TP
B12: Abu Sufyan | C12: =SUM(Staff!K33) -> #REF! | E12: KH | F12: =SUM(Data!M33) -> #REF! | I12: =SUM(F9) -> #REF! | J12: + | M12: Total of ZK,KH,BP | Q12: US Gross
B13: Eisha | C13: =SUM(Staff!L33) -> #REF! | E13: ECG | F13: =SUM(Data!N33) -> #REF! | I13: =SUM(I12,K12) -> #REF! | M13: =SUM(F12,F16,F17) -> #REF! | Q13: US Total | R13: - | S13: US Exp
B14: Shakila | C14: =SUM(Staff!M33) -> #REF! | E14: Csh | F14: =SUM(Data!O33) -> #REF! | Q14: =SUM(F7) -> #REF! | R14: - | S14: =SUM(F21) -> #REF!
B15: Driver K | C15: =SUM(Staff!N33) -> #REF! | E15: Disp (Clinic) purchases | F15: =SUM(Data!P33) -> #REF! | I15: Stock Difference | Q15: =Q14-S14 -> #REF!
B16: Abbas | C16: =SUM(Staff!O33) -> #REF! | E16: ZK | F16: =SUM(Data!Q33) -> #REF! | I16: =I9-I13 -> #REF!
B17: Essai | C17: =SUM(Staff!P33) -> #REF! | E17: BP | F17: =SUM(Data!R33) -> #REF! | Q17: Clinic + US Gross
B18: NS LHV | C18: =SUM(Staff!Q33) -> #REF! | E18: Receivables | F18: =SUM(Data!S33) -> #REF! | Q18: =SUM(Q15) -> #REF!
E19: Store Exp | F19: =SUM(Data!V33) -> #REF! | I19: Store Gross
E20: Dental Exp | F20: =SUM(Data!U33) -> #REF! | I20: Store profit - Store Expances
E21: US Exp | F21: =SUM(Data!T33) -> #REF! | I21: =K5-F19 -> #REF!

Sheet Staff
A1: Date | B1: S.Naeem | C1: Ammar | D1: Noman | E1: Naveed | F1: Baig sb | G1: Bilal MR | H1: Komal | I1: Amir Shah | J1: Adnan | K1: Abu Sufyan | L1: Eisha | M1: Shakila | N1: Driver K | O1: Abbas | P1: Essai | Q1: NS LHV
A2: 1 | B2: =SUM(INDIRECT("'"&TEXT(A2,"00")&"'!O$6")) -> 0 | C2: =SUM(INDIRECT("'"&TEXT(A2,"00")&"'!O$7")) -> 0 | D2: =SUM(INDIRECT("'"&TEXT(A2,"00")&"'!O$8")) -> 0 | E2: =SUM(INDIRECT("'"&TEXT(A2,"00")&"'!O$9")) -> 0 | F2: =SUM(INDIRECT("'"&TEXT(A2,"00")&"'!O$10")) -> 0 | G2: =SUM(INDIRECT("'"&TEXT(A2,"00")&"'!O$11")) -> 0 | H2: =SUM(INDIRECT("'"&TEXT(A2,"00")&"'!O$12")) -> 0 | I2: =SUM(INDIRECT("'"&TEXT(A2,"00")&"'!O$13")) -> 0 | J2: =SUM(INDIRECT("'"&TEXT(A2,"00")&"'!O$14")) -> 0 | K2: =SUM(INDIRECT("'"&TEXT(A2,"00")&"'!O$15")) -> 0 | L2: =SUM(INDIRECT("'"&TEXT(A2,"00")&"'!O$16")) -> 10500 | M2: =SUM(INDIRECT("'"&TEXT(A2,"00")&"'!O$17")) -> 0 | N2: =SUM(INDIRECT("'"&TEXT(A2,"00")&"'!O$18")) -> 0 | O2: =SUM(INDIRECT("'"&TEXT(A2,"00")&"'!O$19")) -> 0 | P2: =SUM(INDIRECT("'"&TEXT(A2,"00")&"'!O$20")) -> 0 | Q2: =SUM(INDIRECT("'"&TEXT(A2,"00")&"'!O$21")) -> 0 | R2: =SUM(INDIRECT("'"&TEXT(A2,"00")&"'!O$22")) -> 0
A3: 2 | B3: =SUM(INDIRECT("'"&TEXT(A3,"00")&"'!O$6")) -> 1280 | C3: =SUM(INDIRECT("'"&TEXT(A3,"00")&"'!O$7")) -> 0 | D3: =SUM(INDIRECT("'"&TEXT(A3,"00")&"'!O$8")) -> 0 | E3: =SUM(INDIRECT("'"&TEXT(A3,"00")&"'!O$9")) -> 0 | F3: =SUM(INDIRECT("'"&TEXT(A3,"00")&"'!O$10")) -> 0 | G3: =SUM(INDIRECT("'"&TEXT(A3,"00")&"'!O$11")) -> 0 | H3: =SUM(INDIRECT("'"&TEXT(A3,"00")&"'!O$12")) -> 0 | I3: =SUM(INDIRECT("'"&TEXT(A3,"00")&"'!O$13")) -> 0 | J3: =SUM(INDIRECT("'"&TEXT(A3,"00")&"'!O$14")) -> 0 | K3: =SUM(INDIRECT("'"&TEXT(A3,"00")&"'!O$15")) -> 0 | L3: =SUM(INDIRECT("'"&TEXT(A3,"00")&"'!O$16")) -> 0 | M3: =SUM(INDIRECT("'"&TEXT(A3,"00")&"'!O$17")) -> 0 | N3: =SUM(INDIRECT("'"&TEXT(A3,"00")&"'!O$18")) -> 0 | O3: =SUM(INDIRECT("'"&TEXT(A3,"00")&"'!O$19")) -> 0 | P3: =SUM(INDIRECT("'"&TEXT(A3,"00")&"'!O$20")) -> 200 | Q3: =SUM(INDIRECT("'"&TEXT(A3,"00")&"'!O$21")) -> 0 | R3: =SUM(INDIRECT("'"&TEXT(A3,"00")&"'!O$22")) -> 0
A4: 3 | B4: =SUM(INDIRECT("'"&TEXT(A4,"00")&"'!O$6")) -> 0 | C4: =SUM(INDIRECT("'"&TEXT(A4,"00")&"'!O$7")) -> 0 | D4: =SUM(INDIRECT("'"&TEXT(A4,"00")&"'!O$8")) -> 0 | E4: =SUM(INDIRECT("'"&TEXT(A4,"00")&"'!O$9")) -> 0 | F4: =SUM(INDIRECT("'"&TEXT(A4,"00")&"'!O$10")) -> 0 | G4: =SUM(INDIRECT("'"&TEXT(A4,"00")&"'!O$11")) -> 0 | H4: =SUM(INDIRECT("'"&TEXT(A4,"00")&"'!O$12")) -> 0 | I4: =SUM(INDIRECT("'"&TEXT(A4,"00")&"'!O$13")) -> 0 | J4: =SUM(INDIRECT("'"&TEXT(A4,"00")&"'!O$14")) -> 0 | K4: =SUM(INDIRECT("'"&TEXT(A4,"00")&"'!O$15")) -> 0 | L4: =SUM(INDIRECT("'"&TEXT(A4,"00")&"'!O$16")) -> 0 | M4: =SUM(INDIRECT("'"&TEXT(A4,"00")&"'!O$17")) -> 0 | N4: =SUM(INDIRECT("'"&TEXT(A4,"00")&"'!O$18")) -> 0 | O4: =SUM(INDIRECT("'"&TEXT(A4,"00")&"'!O$19")) -> 0 | P4: =SUM(INDIRECT("'"&TEXT(A4,"00")&"'!O$20")) -> 0 | Q4: =SUM(INDIRECT("'"&TEXT(A4,"00")&"'!O$21")) -> 0 | R4: =SUM(INDIRECT("'"&TEXT(A4,"00")&"'!O$22")) -> 0
A5: 4 | B5: =SUM(INDIRECT("'"&TEXT(A5,"00")&"'!O$6")) -> 0 | C5: =SUM(INDIRECT("'"&TEXT(A5,"00")&"'!O$7")) -> 0 | D5: =SUM(INDIRECT("'"&TEXT(A5,"00")&"'!O$8")) -> 0 | E5: =SUM(INDIRECT("'"&TEXT(A5,"00")&"'!O$9")) -> 0 | F5: =SUM(INDIRECT("'"&TEXT(A5,"00")&"'!O$10")) -> 0 | G5: =SUM(INDIRECT("'"&TEXT(A5,"00")&"'!O$11")) -> 0 | H5: =SUM(INDIRECT("'"&TEXT(A5,"00")&"'!O$12")) -> 0 | I5: =SUM(INDIRECT("'"&TEXT(A5,"00")&"'!O$13")) -> 0 | J5: =SUM(INDIRECT("'"&TEXT(A5,"00")&"'!O$14")) -> 0 | K5: =SUM(INDIRECT("'"&TEXT(A5,"00")&"'!O$15")) -> 0 | L5: =SUM(INDIRECT("'"&TEXT(A5,"00")&"'!O$16")) -> 0 | M5: =SUM(INDIRECT("'"&TEXT(A5,"00")&"'!O$17")) -> 0 | N5: =SUM(INDIRECT("'"&TEXT(A5,"00")&"'!O$18")) -> 0 | O5: =SUM(INDIRECT("'"&TEXT(A5,"00")&"'!O$19")) -> 0 | P5: =SUM(INDIRECT("'"&TEXT(A5,"00")&"'!O$20")) -> 0 | Q5: =SUM(INDIRECT("'"&TEXT(A5,"00")&"'!O$21")) -> 0 | R5: =SUM(INDIRECT("'"&TEXT(A5,"00")&"'!O$22")) -> 0
A6: 5 | B6: =SUM(INDIRECT("'"&TEXT(A6,"00")&"'!O$6")) -> 1100 | C6: =SUM(INDIRECT("'"&TEXT(A6,"00")&"'!O$7")) -> 0 | D6: =SUM(INDIRECT("'"&TEXT(A6,"00")&"'!O$8")) -> 0 | E6: =SUM(INDIRECT("'"&TEXT(A6,"00")&"'!O$9")) -> 0 | F6: =SUM(INDIRECT("'"&TEXT(A6,"00")&"'!O$10")) -> 0 | G6: =SUM(INDIRECT("'"&TEXT(A6,"00")&"'!O$11")) -> 0 | H6: =SUM(INDIRECT("'"&TEXT(A6,"00")&"'!O$12")) -> 0 | I6: =SUM(INDIRECT("'"&TEXT(A6,"00")&"'!O$13")) -> 0 | J6: =SUM(INDIRECT("'"&TEXT(A6,"00")&"'!O$14")) -> 0 | K6: =SUM(INDIRECT("'"&TEXT(A6,"00")&"'!O$15")) -> 0 | L6: =SUM(INDIRECT("'"&TEXT(A6,"00")&"'!O$16")) -> 0 | M6: =SUM(INDIRECT("'"&TEXT(A6,"00")&"'!O$17")) -> 0 | N6: =SUM(INDIRECT("'"&TEXT(A6,"00")&"'!O$18")) -> 0 | O6: =SUM(INDIRECT("'"&TEXT(A6,"00")&"'!O$19")) -> 0 | P6: =SUM(INDIRECT("'"&TEXT(A6,"00")&"'!O$20")) -> 0 | Q6: =SUM(INDIRECT("'"&TEXT(A6,"00")&"'!O$21")) -> 0 | R6: =SUM(INDIRECT("'"&TEXT(A6,"00")&"'!O$22")) -> 0
A7: 6 | B7: =SUM(INDIRECT("'"&TEXT(A7,"00")&"'!O$6")) -> 0 | C7: =SUM(INDIRECT("'"&TEXT(A7,"00")&"'!O$7")) -> 0 | D7: =SUM(INDIRECT("'"&TEXT(A7,"00")&"'!O$8")) -> 0 | E7: =SUM(INDIRECT("'"&TEXT(A7,"00")&"'!O$9")) -> 0 | F7: =SUM(INDIRECT("'"&TEXT(A7,"00")&"'!O$10")) -> 0 | G7: =SUM(INDIRECT("'"&TEXT(A7,"00")&"'!O$11")) -> 0 | H7: =SUM(INDIRECT("'"&TEXT(A7,"00")&"'!O$12")) -> 0 | I7: =SUM(INDIRECT("'"&TEXT(A7,"00")&"'!O$13")) -> 0 | J7: =SUM(INDIRECT("'"&TEXT(A7,"00")&"'!O$14")) -> 0 | K7: =SUM(INDIRECT("'"&TEXT(A7,"00")&"'!O$15")) -> 0 | L7: =SUM(INDIRECT("'"&TEXT(A7,"00")&"'!O$16")) -> 0 | M7: =SUM(INDIRECT("'"&TEXT(A7,"00")&"'!O$17")) -> 0 | N7: =SUM(INDIRECT("'"&TEXT(A7,"00")&"'!O$18")) -> 0 | O7: =SUM(INDIRECT("'"&TEXT(A7,"00")&"'!O$19")) -> 0 | P7: =SUM(INDIRECT("'"&TEXT(A7,"00")&"'!O$20")) -> 0 | Q7: =SUM(INDIRECT("'"&TEXT(A7,"00")&"'!O$21")) -> 0 | R7: =SUM(INDIRECT("'"&TEXT(A7,"00")&"'!O$22")) -> 0
A8: 7 | B8: =SUM(INDIRECT("'"&TEXT(A8,"00")&"'!O$6")) -> 0 | C8: =SUM(INDIRECT("'"&TEXT(A8,"00")&"'!O$7")) -> 0 | D8: =SUM(INDIRECT("'"&TEXT(A8,"00")&"'!O$8")) -> 0 | E8: =SUM(INDIRECT("'"&TEXT(A8,"00")&"'!O$9")) -> 0 | F8: =SUM(INDIRECT("'"&TEXT(A8,"00")&"'!O$10")) -> 0 | G8: =SUM(INDIRECT("'"&TEXT(A8,"00")&"'!O$11")) -> 0 | H8: =SUM(INDIRECT("'"&TEXT(A8,"00")&"'!O$12")) -> 0 | I8: =SUM(INDIRECT("'"&TEXT(A8,"00")&"'!O$13")) -> 0 | J8: =SUM(INDIRECT("'"&TEXT(A8,"00")&"'!O$14")) -> 0 | K8: =SUM(INDIRECT("'"&TEXT(A8,"00")&"'!O$15")) -> 0 | L8: =SUM(INDIRECT("'"&TEXT(A8,"00")&"'!O$16")) -> 0 | M8: =SUM(INDIRECT("'"&TEXT(A8,"00")&"'!O$17")) -> 0 | N8: =SUM(INDIRECT("'"&TEXT(A8,"00")&"'!O$18")) -> 0 | O8: =SUM(INDIRECT("'"&TEXT(A8,"00")&"'!O$19")) -> 0 | P8: =SUM(INDIRECT("'"&TEXT(A8,"00")&"'!O$20")) -> 0 | Q8: =SUM(INDIRECT("'"&TEXT(A8,"00")&"'!O$21")) -> 0 | R8: =SUM(INDIRECT("'"&TEXT(A8,"00")&"'!O$22")) -> 0
A9: 8 | B9: =SUM(INDIRECT("'"&TEXT(A9,"00")&"'!O$6")) -> 3500 | C9: =SUM(INDIRECT("'"&TEXT(A9,"00")&"'!O$7")) -> 0 | D9: =SUM(INDIRECT("'"&TEXT(A9,"00")&"'!O$8")) -> 0 | E9: =SUM(INDIRECT("'"&TEXT(A9,"00")&"'!O$9")) -> 0 | F9: =SUM(INDIRECT("'"&TEXT(A9,"00")&"'!O$10")) -> 0 | G9: =SUM(INDIRECT("'"&TEXT(A9,"00")&"'!O$11")) -> 0 | H9: =SUM(INDIRECT("'"&TEXT(A9,"00")&"'!O$12")) -> 0 | I9: =SUM(INDIRECT("'"&TEXT(A9,"00")&"'!O$13")) -> 0 | J9: =SUM(INDIRECT("'"&TEXT(A9,"00")&"'!O$14")) -> 0 | K9: =SUM(INDIRECT("'"&TEXT(A9,"00")&"'!O$15")) -> 0 | L9: =SUM(INDIRECT("'"&TEXT(A9,"00")&"'!O$16")) -> 0 | M9: =SUM(INDIRECT("'"&TEXT(A9,"00")&"'!O$17")) -> 0 | N9: =SUM(INDIRECT("'"&TEXT(A9,"00")&"'!O$18")) -> 0 | O9: =SUM(INDIRECT("'"&TEXT(A9,"00")&"'!O$19")) -> 0 | P9: =SUM(INDIRECT("'"&TEXT(A9,"00")&"'!O$20")) -> 0 | Q9: =SUM(INDIRECT("'"&TEXT(A9,"00")&"'!O$21")) -> 0 | R9: =SUM(INDIRECT("'"&TEXT(A9,"00")&"'!O$22")) -> 0
A10: 9 | B10: =SUM(INDIRECT("'"&TEXT(A10,"00")&"'!O$6")) -> 0 | C10: =SUM(INDIRECT("'"&TEXT(A10,"00")&"'!O$7")) -> 0 | D10: =SUM(INDIRECT("'"&TEXT(A10,"00")&"'!O$8")) -> 0 | E10: =SUM(INDIRECT("'"&TEXT(A10,"00")&"'!O$9")) -> 0 | F10: =SUM(INDIRECT("'"&TEXT(A10,"00")&"'!O$10")) -> 0 | G10: =SUM(INDIRECT("'"&TEXT(A10,"00")&"'!O$11")) -> 0 | H10: =SUM(INDIRECT("'"&TEXT(A10,"00")&"'!O$12")) -> 0 | I10: =SUM(INDIRECT("'"&TEXT(A10,"00")&"'!O$13")) -> 0 | J10: =SUM(INDIRECT("'"&TEXT(A10,"00")&"'!O$14")) -> 0 | K10: =SUM(INDIRECT("'"&TEXT(A10,"00")&"'!O$15")) -> 0 | L10: =SUM(INDIRECT("'"&TEXT(A10,"00")&"'!O$16")) -> 0 | M10: =SUM(INDIRECT("'"&TEXT(A10,"00")&"'!O$17")) -> 0 | N10: =SUM(INDIRECT("'"&TEXT(A10,"00")&"'!O$18")) -> 0 | O10: =SUM(INDIRECT("'"&TEXT(A10,"00")&"'!O$19")) -> 0 | P10: =SUM(INDIRECT("'"&TEXT(A10,"00")&"'!O$20")) -> 0 | Q10: =SUM(INDIRECT("'"&TEXT(A10,"00")&"'!O$21")) -> 0 | R10: =SUM(INDIRECT("'"&TEXT(A10,"00")&"'!O$22")) -> 0
A11: 10 | B11: =SUM(INDIRECT("'"&TEXT(A11,"00")&"'!O$6")) -> 0 | C11: =SUM(INDIRECT("'"&TEXT(A11,"00")&"'!O$7")) -> 0 | D11: =SUM(INDIRECT("'"&TEXT(A11,"00")&"'!O$8")) -> 0 | E11: =SUM(INDIRECT("'"&TEXT(A11,"00")&"'!O$9")) -> 0 | F11: =SUM(INDIRECT("'"&TEXT(A11,"00")&"'!O$10")) -> 0 | G11: =SUM(INDIRECT("'"&TEXT(A11,"00")&"'!O$11")) -> 0 | H11: =SUM(INDIRECT("'"&TEXT(A11,"00")&"'!O$12")) -> 0 | I11: =SUM(INDIRECT("'"&TEXT(A11,"00")&"'!O$13")) -> 0 | J11: =SUM(INDIRECT("'"&TEXT(A11,"00")&"'!O$14")) -> 10000 | K11: =SUM(INDIRECT("'"&TEXT(A11,"00")&"'!O$15")) -> 0 | L11: =SUM(INDIRECT("'"&TEXT(A11,"00")&"'!O$16")) -> 0 | M11: =SUM(INDIRECT("'"&TEXT(A11,"00")&"'!O$17")) -> 3750 | N11: =SUM(INDIRECT("'"&TEXT(A11,"00")&"'!O$18")) -> 0 | O11: =SUM(INDIRECT("'"&TEXT(A11,"00")&"'!O$19")) -> 0 | P11: =SUM(INDIRECT("'"&TEXT(A11,"00")&"'!O$20")) -> 0 | Q11: =SUM(INDIRECT("'"&TEXT(A11,"00")&"'!O$21")) -> 0 | R11: =SUM(INDIRECT("'"&TEXT(A11,"00")&"'!O$22")) -> 0
A12: 11 | B12: =SUM(INDIRECT("'"&TEXT(A12,"00")&"'!O$6")) -> 0 | C12: =SUM(INDIRECT("'"&TEXT(A12,"00")&"'!O$7")) -> 0 | D12: =SUM(INDIRECT("'"&TEXT(A12,"00")&"'!O$8")) -> 0 | E12: =SUM(INDIRECT("'"&TEXT(A12,"00")&"'!O$9")) -> 0 | F12: =SUM(INDIRECT("'"&TEXT(A12,"00")&"'!O$10")) -> 0 | G12: =SUM(INDIRECT("'"&TEXT(A12,"00")&"'!O$11")) -> 0 | H12: =SUM(INDIRECT("'"&TEXT(A12,"00")&"'!O$12")) -> 0 | I12: =SUM(INDIRECT("'"&TEXT(A12,"00")&"'!O$13")) -> 0 | J12: =SUM(INDIRECT("'"&TEXT(A12,"00")&"'!O$14")) -> 0 | K12: =SUM(INDIRECT("'"&TEXT(A12,"00")&"'!O$15")) -> 0 | L12: =SUM(INDIRECT("'"&TEXT(A12,"00")&"'!O$16")) -> 0 | M12: =SUM(INDIRECT("'"&TEXT(A12,"00")&"'!O$17")) -> 0 | N12: =SUM(INDIRECT("'"&TEXT(A12,"00")&"'!O$18")) -> 0 | O12: =SUM(INDIRECT("'"&TEXT(A12,"00")&"'!O$19")) -> 4500 | P12: =SUM(INDIRECT("'"&TEXT(A12,"00")&"'!O$20")) -> 0 | Q12: =SUM(INDIRECT("'"&TEXT(A12,"00")&"'!O$21")) -> 0 | R12: =SUM(INDIRECT("'"&TEXT(A12,"00")&"'!O$22")) -> 0
A13: 12 | B13: =SUM(INDIRECT("'"&TEXT(A13,"00")&"'!O$6")) -> 0 | C13: =SUM(INDIRECT("'"&TEXT(A13,"00")&"'!O$7")) -> 0 | D13: =SUM(INDIRECT("'"&TEXT(A13,"00")&"'!O$8")) -> 0 | E13: =SUM(INDIRECT("'"&TEXT(A13,"00")&"'!O$9")) -> 0 | F13: =SUM(INDIRECT("'"&TEXT(A13,"00")&"'!O$10")) -> 0 | G13: =SUM(INDIRECT("'"&TEXT(A13,"00")&"'!O$11")) -> 0 | H13: =SUM(INDIRECT("'"&TEXT(A13,"00")&"'!O$12")) -> 0 | I13: =SUM(INDIRECT("'"&TEXT(A13,"00")&"'!O$13")) -> 0 | J13: =SUM(INDIRECT("'"&TEXT(A13,"00")&"'!O$14")) -> 0 | K13: =SUM(INDIRECT("'"&TEXT(A13,"00")&"'!O$15")) -> 0 | L13: =SUM(INDIRECT("'"&TEXT(A13,"00")&"'!O$16")) -> 0 | M13: =SUM(INDIRECT("'"&TEXT(A13,"00")&"'!O$17")) -> 0 | N13: =SUM(INDIRECT("'"&TEXT(A13,"00")&"'!O$18")) -> 0 | O13: =SUM(INDIRECT("'"&TEXT(A13,"00")&"'!O$19")) -> 0 | P13: =SUM(INDIRECT("'"&TEXT(A13,"00")&"'!O$20")) -> 0 | Q13: =SUM(INDIRECT("'"&TEXT(A13,"00")&"'!O$21")) -> 0 | R13: =SUM(INDIRECT("'"&TEXT(A13,"00")&"'!O$22")) -> 0
... A32: 31 | B32: =SUM(INDIRECT("'"&TEXT(A32,"00")&"'!O$6")) -> #REF! | C32: =SUM(INDIRECT("'"&TEXT(A32,"00")&"'!O$7")) -> #REF! | D32: =SUM(INDIRECT("'"&TEXT(A32,"00")&"'!O$8")) -> #REF! | E32: =SUM(INDIRECT("'"&TEXT(A32,"00")&"'!O$9")) -> #REF! | F32: =SUM(INDIRECT("'"&TEXT(A32,"00")&"'!O$10")) -> #REF! | G32: =SUM(INDIRECT("'"&TEXT(A32,"00")&"'!O$11")) -> #REF! | H32: =SUM(INDIRECT("'"&TEXT(A32,"00")&"'!O$12")) -> #REF! | I32: =SUM(INDIRECT("'"&TEXT(A32,"00")&"'!O$13")) -> #REF! | J32: =SUM(INDIRECT("'"&TEXT(A32,"00")&"'!O$14")) -> #REF! | K32: =SUM(INDIRECT("'"&TEXT(A32,"00")&"'!O$15")) -> #REF! | L32: =SUM(INDIRECT("'"&TEXT(A32,"00")&"'!O$16")) -> #REF! | M32: =SUM(INDIRECT("'"&TEXT(A32,"00")&"'!O$17")) -> #REF! | N32: =SUM(INDIRECT("'"&TEXT(A32,"00")&"'!O$18")) -> #REF! | O32: =SUM(INDIRECT("'"&TEXT(A32,"00")&"'!O$19")) -> #REF! | P32: =SUM(INDIRECT("'"&TEXT(A32,"00")&"'!O$20")) -> #REF! | Q32: =SUM(INDIRECT("'"&TEXT(A32,"00")&"'!O$21")) -> #REF! | R32: =SUM(INDIRECT("'"&TEXT(A32,"00")&"'!O$22")) -> #REF!
A33: Total | B33: =SUM(B2:B32) -> #REF! | C33: =SUM(C2:C32) -> #REF! | D33: =SUM(D2:D32) -> #REF! | E33: =SUM(E2:E32) -> #REF! | F33: =SUM(F2:F32) -> #REF! | G33: =SUM(G2:G32) -> #REF! | H33: =SUM(H2:H32) -> #REF! | I33: =SUM(I2:I32) -> #REF! | ... R33: =SUM(R2:R32) -> #REF!
E37: =SUM(B33:R34) -> #REF!

Sheet Data
A1: Date | B1: Dr | C1: Cr | D1: Purchase Med (St) | E1: Sale Med (St) | F1: Home Exp | G1: Clinic Exp | H1: US | I1: Disp inc | J1: St Sale | K1: LB inc | L1: LB Exp | M1: KH | N1: ECG | O1: CSH | P1: Disp purchase | Q1: ZK | R1: BP | S1: Receivables | T1: US Exp | U1: Dental Exp | V1: Store Exp
A2: 1 | B2: =SUM(INDIRECT("'"&TEXT(A2,"00")&"'!C$35")) -> 186663 | C2: =SUM(INDIRECT("'"&TEXT(A2,"00")&"'!F$35")) -> 187946 | D2: =SUM(INDIRECT("'"&TEXT(A2,"00")&"'!C$6")) -> 51233 | E2: =SUM(INDIRECT("'"&TEXT(A2,"00")&"'!J$23")) -> 101429 | F2: =SUM(INDIRECT("'"&TEXT(A2,"00")&"'!C$10")) -> 16860 | G2: =SUM(INDIRECT("'"&TEXT(A2,"00")&"'!C$8")) -> 1620 | H2: =SUM(INDIRECT("'"&TEXT(A2,"00")&"'!F$9")) -> 79000 | I2: =SUM(INDIRECT("'"&TEXT(A2,"00")&"'!F$7")) -> 28700 | J2: =SUM(INDIRECT("'"&TEXT(A2,"00")&"'!F$10")) -> 36500 | K2: =SUM(INDIRECT("'"&TEXT(A2,"00")&"'!F$8")) -> 450 | L2: =SUM(INDIRECT("'"&TEXT(A2,"00")&"'!C$9")) -> 0 | M2: =SUM(INDIRECT("'"&TEXT(A2,"00")&"'!C$32")) -> 3350 | N2: =SUM(INDIRECT("'"&TEXT(A2,"00")&"'!F$11")) -> 0 | O2: =SUM(INDIRECT("'"&TEXT(A2,"00")&"'!B$38")) -> 89000 | P2: =SUM(INDIRECT("'"&TEXT(A2,"00")&"'!C$7")) -> 0 | Q2: =SUM(INDIRECT("'"&TEXT(A2,"00")&"'!C$31")) -> 0 | R2: =SUM(INDIRECT("'"&TEXT(A2,"00")&"'!C$33")) -> 0 | S2: =SUM(INDIRECT("'"&TEXT(A2,"00")&"'!O$35")) -> 0 | T2: =SUM(INDIRECT("'"&TEXT(A2,"00")&"'!C$11")) -> 0 | U2: =SUM(INDIRECT("'"&TEXT(A2,"00")&"'!C$12")) -> 200 | V2: =SUM(INDIRECT("'"&TEXT(A2,"00")&"'!C$13")) -> 0
A3: 2 | B3: =SUM(INDIRECT("'"&TEXT(A3,"00")&"'!C$35")) -> 170645 | C3: =SUM(INDIRECT("'"&TEXT(A3,"00")&"'!F$35")) -> 172865 | D3: =SUM(INDIRECT("'"&TEXT(A3,"00")&"'!C$6")) -> 7485 | E3: =SUM(INDIRECT("'"&TEXT(A3,"00")&"'!J$23")) -> 13630 | F3: =SUM(INDIRECT("'"&TEXT(A3,"00")&"'!C$10")) -> 17940 | G3: =SUM(INDIRECT("'"&TEXT(A3,"00")&"'!C$8")) -> 2040 | H3: =SUM(INDIRECT("'"&TEXT(A3,"00")&"'!F$9")) -> 92000 | I3: =SUM(INDIRECT("'"&TEXT(A3,"00")&"'!F$7")) -> 38850 | J3: =SUM(INDIRECT("'"&TEXT(A3,"00")&"'!F$10")) -> 37865 | K3: =SUM(INDIRECT("'"&TEXT(A3,"00")&"'!F$8")) -> 250 | L3: =SUM(INDIRECT("'"&TEXT(A3,"00")&"'!C$9")) -> 0 | M3: =SUM(INDIRECT("'"&TEXT(A3,"00")&"'!C$32")) -> 6500 | N3: =SUM(INDIRECT("'"&TEXT(A3,"00")&"'!F$11")) -> 1000 | O3: =SUM(INDIRECT("'"&TEXT(A3,"00")&"'!B$38")) -> 100000 | P3: =SUM(INDIRECT("'"&TEXT(A3,"00")&"'!C$7")) -> 2190 | Q3: =SUM(INDIRECT("'"&TEXT(A3,"00")&"'!C$31")) -> 0 | R3: =SUM(INDIRECT("'"&TEXT(A3,"00")&"'!C$33")) -> 1500 | S3: =SUM(INDIRECT("'"&TEXT(A3,"00")&"'!O$35")) -> 0 | T3: =SUM(INDIRECT("'"&TEXT(A3,"00")&"'!C$11")) -> 400 | U3: =SUM(INDIRECT("'"&TEXT(A3,"00")&"'!C$12")) -> 200 | V3: =SUM(INDIRECT("'"&TEXT(A3,"00")&"'!C$13")) -> 0
A4: 3 | B4: =SUM(INDIRECT("'"&TEXT(A4,"00")&"'!C$35")) -> 263015 | C4: =SUM(INDIRECT("'"&TEXT(A4,"00")&"'!F$35")) -> 263180 | D4: =SUM(INDIRECT("'"&TEXT(A4,"00")&"'!C$6")) -> 39395 | E4: =SUM(INDIRECT("'"&TEXT(A4,"00")&"'!J$23")) -> 82296 | F4: =SUM(INDIRECT("'"&TEXT(A4,"00")&"'!C$10")) -> 134420 | G4: =SUM(INDIRECT("'"&TEXT(A4,"00")&"'!C$8")) -> 7280 | H4: =SUM(INDIRECT("'"&TEXT(A4,"00")&"'!F$9")) -> 80000 | I4: =SUM(INDIRECT("'"&TEXT(A4,"00")&"'!F$7")) -> 25350 | J4: =SUM(INDIRECT("'"&TEXT(A4,"00")&"'!F$10")) -> 34680 | K4: =SUM(INDIRECT("'"&TEXT(A4,"00")&"'!F$8")) -> 550 | L4: =SUM(INDIRECT("'"&TEXT(A4,"00")&"'!C$9")) -> 4250 | M4: =SUM(INDIRECT("'"&TEXT(A4,"00")&"'!C$32")) -> 2500 | N4: =SUM(INDIRECT("'"&TEXT(A4,"00")&"'!F$11")) -> 1000 | O4: =SUM(INDIRECT("'"&TEXT(A4,"00")&"'!B$38")) -> 60000 | P4: =SUM(INDIRECT("'"&TEXT(A4,"00")&"'!C$7")) -> 1670 | Q4: =SUM(INDIRECT("'"&TEXT(A4,"00")&"'!C$31")) -> 0 | R4: =SUM(INDIRECT("'"&TEXT(A4,"00")&"'!C$33")) -> 6000 | S4: =SUM(INDIRECT("'"&TEXT(A4,"00")&"'!O$35")) -> 0 | T4: =SUM(INDIRECT("'"&TEXT(A4,"00")&"'!C$11")) -> 800 | U4: =SUM(INDIRECT("'"&TEXT(A4,"00")&"'!C$12")) -> 200 | V4: =SUM(INDIRECT("'"&TEXT(A4,"00")&"'!C$13")) -> 0
A5: 4 | B5: =SUM(INDIRECT("'"&TEXT(A5,"00")&"'!C$35")) -> 126170 | C5: =SUM(INDIRECT("'"&TEXT(A5,"00")&"'!F$35")) -> 126240 | D5: =SUM(INDIRECT("'"&TEXT(A5,"00")&"'!C$6")) -> 0 | E5: =SUM(INDIRECT("'"&TEXT(A5,"00")&"'!J$23")) -> 0 | F5: =SUM(INDIRECT("'"&TEXT(A5,"00")&"'!C$10")) -> 10760 | G5: =SUM(INDIRECT("'"&TEXT(A5,"00")&"'!C$8")) -> 1040 | H5: =SUM(INDIRECT("'"&TEXT(A5,"00")&"'!F$9")) -> 71000 | I5: =SUM(INDIRECT("'"&TEXT(A5,"00")&"'!F$7")) -> 22700 | J5: =SUM(INDIRECT("'"&TEXT(A5,"00")&"'!F$10")) -> 29490 | K5: =SUM(INDIRECT("'"&TEXT(A5,"00")&"'!F$8")) -> 350 | L5: =SUM(INDIRECT("'"&TEXT(A5,"00")&"'!C$9")) -> 0 | M5: =SUM(INDIRECT("'"&TEXT(A5,"00")&"'!C$32")) -> 300 | N5: =SUM(INDIRECT("'"&TEXT(A5,"00")&"'!F$11")) -> 0 | O5: =SUM(INDIRECT("'"&TEXT(A5,"00")&"'!B$38")) -> 96500 | P5: =SUM(INDIRECT("'"&TEXT(A5,"00")&"'!C$7")) -> 0 | Q5: =SUM(INDIRECT("'"&TEXT(A5,"00")&"'!C$31")) -> 0 | R5: =SUM(INDIRECT("'"&TEXT(A5,"00")&"'!C$33")) -> 0 | S5: =SUM(INDIRECT("'"&TEXT(A5,"00")&"'!O$35")) -> 0 | T5: =SUM(INDIRECT("'"&TEXT(A5,"00")&"'!C$11")) -> 0 | U5: =SUM(INDIRECT("'"&TEXT(A5,"00")&"'!C$12")) -> 300 | V5: =SUM(INDIRECT("'"&TEXT(A5,"00")&"'!C$13")) -> 0
A6: 5 | B6: =SUM(INDIRECT("'"&TEXT(A6,"00")&"'!C$35")) -> 173339 | C6: =SUM(INDIRECT("'"&TEXT(A6,"00")&"'!F$35")) -> 173399 | D6: =SUM(INDIRECT("'"&TEXT(A6,"00")&"'!C$6")) -> 4379 | E6: =SUM(INDIRECT("'"&TEXT(A6,"00")&"'!J$23")) -> 11911 | F6: =SUM(INDIRECT("'"&TEXT(A6,"00")&"'!C$10")) -> 24840 | G6: =SUM(INDIRECT("'"&TEXT(A6,"00")&"'!C$8")) -> 1800 | H6: =SUM(INDIRECT("'"&TEXT(A6,"00")&"'!F$9")) -> 85300 | I6: =SUM(INDIRECT("'"&TEXT(A6,"00")&"'!F$7")) -> 26900 | J6: =SUM(INDIRECT("'"&TEXT(A6,"00")&"'!F$10")) -> 46479 | K6: =SUM(INDIRECT("'"&TEXT(A6,"00")&"'!F$8")) -> 1950 | L6: =SUM(INDIRECT("'"&TEXT(A6,"00")&"'!C$9")) -> 0 | M6: =SUM(INDIRECT("'"&TEXT(A6,"00")&"'!C$32")) -> 3200 | N6: =SUM(INDIRECT("'"&TEXT(A6,"00")&"'!F$11")) -> 0 | O6: =SUM(INDIRECT("'"&TEXT(A6,"00")&"'!B$38")) -> 132000 | P6: =SUM(INDIRECT("'"&TEXT(A6,"00")&"'!C$7")) -> 1150 | Q6: =SUM(INDIRECT("'"&TEXT(A6,"00")&"'!C$31")) -> 0 | R6: =SUM(INDIRECT("'"&TEXT(A6,"00")&"'!C$33")) -> 0 | S6: =SUM(INDIRECT("'"&TEXT(A6,"00")&"'!O$35")) -> 0 | T6: =SUM(INDIRECT("'"&TEXT(A6,"00")&"'!C$11")) -> 0 | U6: =SUM(INDIRECT("'"&TEXT(A6,"00")&"'!C$12")) -> 0 | V6: =SUM(INDIRECT("'"&TEXT(A6,"00")&"'!C$13")) -> 0
A7: 6 | B7: =SUM(INDIRECT("'"&TEXT(A7,"00")&"'!C$35")) -> 193608 | C7: =SUM(INDIRECT("'"&TEXT(A7,"00")&"'!F$35")) -> 193628 | D7: =SUM(INDIRECT("'"&TEXT(A7,"00")&"'!C$6")) -> 860 | E7: =SUM(INDIRECT("'"&TEXT(A7,"00")&"'!J$23")) -> 1000 | F7: =SUM(INDIRECT("'"&TEXT(A7,"00")&"'!C$10")) -> 18548 | G7: =SUM(INDIRECT("'"&TEXT(A7,"00")&"'!C$8")) -> 1780 | H7: =SUM(INDIRECT("'"&TEXT(A7,"00")&"'!F$9")) -> 121300 | I7: =SUM(INDIRECT("'"&TEXT(A7,"00")&"'!F$7")) -> 32750 | J7: =SUM(INDIRECT("'"&TEXT(A7,"00")&"'!F$10")) -> 33458 | K7: =SUM(INDIRECT("'"&TEXT(A7,"00")&"'!F$8")) -> 1250 | L7: =SUM(INDIRECT("'"&TEXT(A7,"00")&"'!C$9")) -> 0 | M7: =SUM(INDIRECT("'"&TEXT(A7,"00")&"'!C$32")) -> 6000 | N7: =SUM(INDIRECT("'"&TEXT(A7,"00")&"'!F$11")) -> 0 | O7: =SUM(INDIRECT("'"&TEXT(A7,"00")&"'!B$38")) -> 103000 | P7: =SUM(INDIRECT("'"&TEXT(A7,"00")&"'!C$7")) -> 15710 | Q7: =SUM(INDIRECT("'"&TEXT(A7,"00")&"'!C$31")) -> 2200 | R7: =SUM(INDIRECT("'"&TEXT(A7,"00")&"'!C$33")) -> 8000 | S7: =SUM(INDIRECT("'"&TEXT(A7,"00")&"'!O$35")) -> 0 | T7: =SUM(INDIRECT("'"&TEXT(A7,"00")&"'!C$11")) -> 1000 | U7: =SUM(INDIRECT("'"&TEXT(A7,"00")&"'!C$12")) -> 200 | V7: =SUM(INDIRECT("'"&TEXT(A7,"00")&"'!C$13")) -> 0
A8: 7 | B8: =SUM(INDIRECT("'"&TEXT(A8,"00")&"'!C$35")) -> 163393 | C8: =SUM(INDIRECT("'"&TEXT(A8,"00")&"'!F$35")) -> 163383 | D8: =SUM(INDIRECT("'"&TEXT(A8,"00")&"'!C$6")) -> 24208 | E8: =SUM(INDIRECT("'"&TEXT(A8,"00")&"'!J$23")) -> 39842 | F8: =SUM(INDIRECT("'"&TEXT(A8,"00")&"'!C$10")) -> 10300 | G8: =SUM(INDIRECT("'"&TEXT(A8,"00")&"'!C$8")) -> 2770 | H8: =SUM(INDIRECT("'"&TEXT(A8,"00")&"'!F$9")) -> 80000 | I8: =SUM(INDIRECT("'"&TEXT(A8,"00")&"'!F$7")) -> 23150 | J8: =SUM(INDIRECT("'"&TEXT(A8,"00")&"'!F$10")) -> 30883 | K8: =SUM(INDIRECT("'"&TEXT(A8,"00")&"'!F$8")) -> 1150 | L8: =SUM(INDIRECT("'"&TEXT(A8,"00")&"'!C$9")) -> 0 | M8: =SUM(INDIRECT("'"&TEXT(A8,"00")&"'!C$32")) -> 4500 | N8: =SUM(INDIRECT("'"&TEXT(A8,"00")&"'!F$11")) -> 0 | O8: =SUM(INDIRECT("'"&TEXT(A8,"00")&"'!B$38")) -> 78000 | P8: =SUM(INDIRECT("'"&TEXT(A8,"00")&"'!C$7")) -> 905 | Q8: =SUM(INDIRECT("'"&TEXT(A8,"00")&"'!C$31")) -> 200 | R8: =SUM(INDIRECT("'"&TEXT(A8,"00")&"'!C$33")) -> 0 | S8: =SUM(INDIRECT("'"&TEXT(A8,"00")&"'!O$35")) -> 0 | T8: =SUM(INDIRECT("'"&TEXT(A8,"00")&"'!C$11")) -> 0 | U8: =SUM(INDIRECT("'"&TEXT(A8,"00")&"'!C$12")) -> 1800 | V8: =SUM(INDIRECT("'"&TEXT(A8,"00")&"'!C$13")) -> 0
A9: 8 | B9: =SUM(INDIRECT("'"&TEXT(A9,"00")&"'!C$35")) -> 168354 | C9: =SUM(INDIRECT("'"&TEXT(A9,"00")&"'!F$35")) -> 169051 | D9: =SUM(INDIRECT("'"&TEXT(A9,"00")&"'!C$6")) -> 6914 | E9: =SUM(INDIRECT("'"&TEXT(A9,"00")&"'!J$23")) -> 13275 | F9: =SUM(INDIRECT("'"&TEXT(A9,"00")&"'!C$10")) -> 15910 | G9: =SUM(INDIRECT("'"&TEXT(A9,"00")&"'!C$8")) -> 13210 | H9: =SUM(INDIRECT("'"&TEXT(A9,"00")&"'!F$9")) -> 91900 | I9: =SUM(INDIRECT("'"&TEXT(A9,"00")&"'!F$7")) -> 30100 | J9: =SUM(INDIRECT("'"&TEXT(A9,"00")&"'!F$10")) -> 30601 | K9: =SUM(INDIRECT("'"&TEXT(A9,"00")&"'!F$8")) -> 750 | L9: =SUM(INDIRECT("'"&TEXT(A9,"00")&"'!C$9")) -> 0 | M9: =SUM(INDIRECT("'"&TEXT(A9,"00")&"'!C$32")) -> 0 | N9: =SUM(INDIRECT("'"&TEXT(A9,"00")&"'!F$11")) -> 0 | O9: =SUM(INDIRECT("'"&TEXT(A9,"00")&"'!B$38")) -> 113000 | P9: =SUM(INDIRECT("'"&TEXT(A9,"00")&"'!C$7")) -> 1700 | Q9: =SUM(INDIRECT("'"&TEXT(A9,"00")&"'!C$31")) -> 0 | R9: =SUM(INDIRECT("'"&TEXT(A9,"00")&"'!C$33")) -> 0 | S9: =SUM(INDIRECT("'"&TEXT(A9,"00")&"'!O$35")) -> 0 | T9: =SUM(INDIRECT("'"&TEXT(A9,"00")&"'!C$11")) -> 0 | U9: =SUM(INDIRECT("'"&TEXT(A9,"00")&"'!C$12")) -> 700 | V9: =SUM(INDIRECT("'"&TEXT(A9,"00")&"'!C$13")) -> 0
A10: 9 | B10: =SUM(INDIRECT("'"&TEXT(A10,"00")&"'!C$35")) -> 216572 | C10: =SUM(INDIRECT("'"&TEXT(A10,"00")&"'!F$35")) -> 216422 | D10: =SUM(INDIRECT("'"&TEXT(A10,"00")&"'!C$6")) -> 8709 | E10: =SUM(INDIRECT("'"&TEXT(A10,"00")&"'!J$23")) -> 16273 | F10: =SUM(INDIRECT("'"&TEXT(A10,"00")&"'!C$10")) -> 10300 | G10: =SUM(INDIRECT("'"&TEXT(A10,"00")&"'!C$8")) -> 3540 | H10: =SUM(INDIRECT("'"&TEXT(A10,"00")&"'!F$9")) -> 72000 | I10: =SUM(INDIRECT("'"&TEXT(A10,"00")&"'!F$7")) -> 26950 | J10: =SUM(INDIRECT("'"&TEXT(A10,"00")&"'!F$10")) -> 33299 | K10: =SUM(INDIRECT("'"&TEXT(A10,"00")&"'!F$8")) -> 850 | L10: =SUM(INDIRECT("'"&TEXT(A10,"00")&"'!C$9")) -> 0 | M10: =SUM(INDIRECT("'"&TEXT(A10,"00")&"'!C$32")) -> 1000 | N10: =SUM(INDIRECT("'"&TEXT(A10,"00")&"'!F$11")) -> 0 | O10: =SUM(INDIRECT("'"&TEXT(A10,"00")&"'!B$38")) -> 100000 | P10: =SUM(INDIRECT("'"&TEXT(A10,"00")&"'!C$7")) -> 69923 | Q10: =SUM(INDIRECT("'"&TEXT(A10,"00")&"'!C$31")) -> 0 | R10: =SUM(INDIRECT("'"&TEXT(A10,"00")&"'!C$33")) -> 0 | S10: =SUM(INDIRECT("'"&TEXT(A10,"00")&"'!O$35")) -> 0 | T10: =SUM(INDIRECT("'"&TEXT(A10,"00")&"'!C$11")) -> 0 | U10: =SUM(INDIRECT("'"&TEXT(A10,"00")&"'!C$12")) -> 200 | V10: =SUM(INDIRECT("'"&TEXT(A10,"00")&"'!C$13")) -> 0
A11: 10 | B11: =SUM(INDIRECT("'"&TEXT(A11,"00")&"'!C$35")) -> 182120 | C11: =SUM(INDIRECT("'"&TEXT(A11,"00")&"'!F$35")) -> 182560 | D11: =SUM(INDIRECT("'"&TEXT(A11,"00")&"'!C$6")) -> 4890 | E11: =SUM(INDIRECT("'"&TEXT(A11,"00")&"'!J$23")) -> 13200 | F11: =SUM(INDIRECT("'"&TEXT(A11,"00")&"'!C$10")) -> 20130 | G11: =SUM(INDIRECT("'"&TEXT(A11,"00")&"'!C$8")) -> 1670 | H11: =SUM(INDIRECT("'"&TEXT(A11,"00")&"'!F$9")) -> 81100 | I11: =SUM(INDIRECT("'"&TEXT(A11,"00")&"'!F$7")) -> 42450 | J11: =SUM(INDIRECT("'"&TEXT(A11,"00")&"'!F$10")) -> 45410 | K11: =SUM(INDIRECT("'"&TEXT(A11,"00")&"'!F$8")) -> 700 | L11: =SUM(INDIRECT("'"&TEXT(A11,"00")&"'!C$9")) -> 1150 | M11: =SUM(INDIRECT("'"&TEXT(A11,"00")&"'!C$32")) -> 2900 | N11: =SUM(INDIRECT("'"&TEXT(A11,"00")&"'!F$11")) -> 0 | O11: =SUM(INDIRECT("'"&TEXT(A11,"00")&"'!B$38")) -> 72000 | P11: =SUM(INDIRECT("'"&TEXT(A11,"00")&"'!C$7")) -> 2630 | Q11: =SUM(INDIRECT("'"&TEXT(A11,"00")&"'!C$31")) -> 0 | R11: =SUM(INDIRECT("'"&TEXT(A11,"00")&"'!C$33")) -> 0 | S11: =SUM(INDIRECT("'"&TEXT(A11,"00")&"'!O$35")) -> 0 | T11: =SUM(INDIRECT("'"&TEXT(A11,"00")&"'!C$11")) -> 0 | U11: =SUM(INDIRECT("'"&TEXT(A11,"00")&"'!C$12")) -> 200 | V11: =SUM(INDIRECT("'"&TEXT(A11,"00")&"'!C$13")) -> 0
A12: 11 | B12: =SUM(INDIRECT("'"&TEXT(A12,"00")&"'!C$35")) -> 149840 | C12: =SUM(INDIRECT("'"&TEXT(A12,"00")&"'!F$35")) -> 149310 | D12: =SUM(INDIRECT("'"&TEXT(A12,"00")&"'!C$6")) -> 0 | E12: =SUM(INDIRECT("'"&TEXT(A12,"00")&"'!J$23")) -> 0 | F12: =SUM(INDIRECT("'"&TEXT(A12,"00")&"'!C$10")) -> 15100 | G12: =SUM(INDIRECT("'"&TEXT(A12,"00")&"'!C$8")) -> 52230 | H12: =SUM(INDIRECT("'"&TEXT(A12,"00")&"'!F$9")) -> 66300 | I12: =SUM(INDIRECT("'"&TEXT(A12,"00")&"'!F$7")) -> 28600 | J12: =SUM(INDIRECT("'"&TEXT(A12,"00")&"'!F$10")) -> 42160 | K12: =SUM(INDIRECT("'"&TEXT(A12,"00")&"'!F$8")) -> 1250 | L12: =SUM(INDIRECT("'"&TEXT(A12,"00")&"'!C$9")) -> 0 | M12: =SUM(INDIRECT("'"&TEXT(A12,"00")&"'!C$32")) -> 0 | N12: =SUM(INDIRECT("'"&TEXT(A12,"00")&"'!F$11")) -> 0 | O12: =SUM(INDIRECT("'"&TEXT(A12,"00")&"'!B$38")) -> 50000 | P12: =SUM(INDIRECT("'"&TEXT(A12,"00")&"'!C$7")) -> 0 | Q12: =SUM(INDIRECT("'"&TEXT(A12,"00")&"'!C$31")) -> 200 | R12: =SUM(INDIRECT("'"&TEXT(A12,"00")&"'!C$33")) -> 0 | S12: =SUM(INDIRECT("'"&TEXT(A12,"00")&"'!O$35")) -> 750 | T12: =SUM(INDIRECT("'"&TEXT(A12,"00")&"'!C$11")) -> 0 | U12: =SUM(INDIRECT("'"&TEXT(A12,"00")&"'!C$12")) -> 100 | V12: =SUM(INDIRECT("'"&TEXT(A12,"00")&"'!C$13")) -> 0
A13: 12 | B13: =SUM(INDIRECT("'"&TEXT(A13,"00")&"'!C$35")) -> 204629 | C13: =SUM(INDIRECT("'"&TEXT(A13,"00")&"'!F$35")) -> 205484 | D13: =SUM(INDIRECT("'"&TEXT(A13,"00")&"'!C$6")) -> 34469 | E13: =SUM(INDIRECT("'"&TEXT(A13,"00")&"'!J$23")) -> 82750 | F13: =SUM(INDIRECT("'"&TEXT(A13,"00")&"'!C$10")) -> 15000 | G13: =SUM(INDIRECT("'"&TEXT(A13,"00")&"'!C$8")) -> 8530 | H13: =SUM(INDIRECT("'"&TEXT(A13,"00")&"'!F$9")) -> 98500 | I13: =SUM(INDIRECT("'"&TEXT(A13,"00")&"'!F$7")) -> 51100 | J13: =SUM(INDIRECT("'"&TEXT(A13,"00")&"'!F$10")) -> 36834 | K13: =SUM(INDIRECT("'"&TEXT(A13,"00")&"'!F$8")) -> 1050 | L13: =SUM(INDIRECT("'"&TEXT(A13,"00")&"'!C$9")) -> 0 | M13: =SUM(INDIRECT("'"&TEXT(A13,"00")&"'!C$32")) -> 3500 | N13: =SUM(INDIRECT("'"&TEXT(A13,"00")&"'!F$11")) -> 0 | O13: =SUM(INDIRECT("'"&TEXT(A13,"00")&"'!B$38")) -> 80000 | P13: =SUM(INDIRECT("'"&TEXT(A13,"00")&"'!C$7")) -> 4880 | Q13: =SUM(INDIRECT("'"&TEXT(A13,"00")&"'!C$31")) -> 200 | R13: =SUM(INDIRECT("'"&TEXT(A13,"00")&"'!C$33")) -> 0 | S13: =SUM(INDIRECT("'"&TEXT(A13,"00")&"'!O$35")) -> 0 | T13: =SUM(INDIRECT("'"&TEXT(A13,"00")&"'!C$11")) -> 0 | U13: =SUM(INDIRECT("'"&TEXT(A13,"00")&"'!C$12")) -> 700 | V13: =SUM(INDIRECT("'"&TEXT(A13,"00")&"'!C$13")) -> 0
... A32: 31 | B32: =SUM(INDIRECT("'"&TEXT(A32,"00")&"'!C$35")) -> #REF! | C32: =SUM(INDIRECT("'"&TEXT(A32,"00")&"'!F$35")) -> #REF! | D32: =SUM(INDIRECT("'"&TEXT(A32,"00")&"'!C$6")) -> #REF! | E32: =SUM(INDIRECT("'"&TEXT(A32,"00")&"'!J$23")) -> #REF! | F32: =SUM(INDIRECT("'"&TEXT(A32,"00")&"'!C$10")) -> #REF! | G32: =SUM(INDIRECT("'"&TEXT(A32,"00")&"'!C$8")) -> #REF! | H32: =SUM(INDIRECT("'"&TEXT(A32,"00")&"'!F$9")) -> #REF! | I32: =SUM(INDIRECT("'"&TEXT(A32,"00")&"'!F$7")) -> #REF! | J32: =SUM(INDIRECT("'"&TEXT(A32,"00")&"'!F$10")) -> #REF! | K32: =SUM(INDIRECT("'"&TEXT(A32,"00")&"'!F$8")) -> #REF! | L32: =SUM(INDIRECT("'"&TEXT(A32,"00")&"'!C$9")) -> #REF! | M32: =SUM(INDIRECT("'"&TEXT(A32,"00")&"'!C$32")) -> #REF! | N32: =SUM(INDIRECT("'"&TEXT(A32,"00")&"'!F$11")) -> #REF! | O32: =SUM(INDIRECT("'"&TEXT(A32,"00")&"'!B$38")) -> #REF! | P32: =SUM(INDIRECT("'"&TEXT(A32,"00")&"'!C$7")) -> #REF! | Q32: =SUM(INDIRECT("'"&TEXT(A32,"00")&"'!C$31")) -> #REF! | R32: =SUM(INDIRECT("'"&TEXT(A32,"00")&"'!C$33")) -> #REF! | S32: =SUM(INDIRECT("'"&TEXT(A32,"00")&"'!O$35")) -> #REF! | T32: =SUM(INDIRECT("'"&TEXT(A32,"00")&"'!C$11")) -> #REF! | U32: =SUM(INDIRECT("'"&TEXT(A32,"00")&"'!C$12")) -> #REF! | V32: =SUM(INDIRECT("'"&TEXT(A32,"00")&"'!C$13")) -> #REF!
A33: Total | B33: =SUM(B2:B32) -> #REF! | C33: =SUM(C2:C32) -> #REF! | D33: =SUM(D2:D32) -> #REF! | E33: =SUM(E2:E32) -> #REF! | F33: =SUM(F2:F32) -> #REF! | G33: =SUM(G2:G32) -> #REF! | H33: =SUM(H2:H32) -> #REF! | I33: =SUM(I2:I32) -> #REF! | ... W33: =SUM(W2:W32) -> 0

Sheet 01
B5: Debit (Expences) | E5: Credit ( Income) | H5: Dispensary Purchases | L5: US Total | N5: Staff & Vendors | Q5: Dental Exp | T5: Clinic Bills
B6: Store Med Purchases | C6: 51233 | E6: Daraz Cash | F6: 5800 | L6: 73000 | N6: S.Naeem | R6: 200 | T6: 26400
B7: Dispensary Purchases | E7: Clinic Pt + Dispensary Inc | F7: 28700 | L7: 6000 | N7: Ammar | T7: 1300
B8: Clinic Expenses | C8: 1620 | E8: LB | F8: 450 | N8: Noman | T8: 1000
B9: LB Expenses | E9: US | F9: 79000 | N9: Naveed
B10: Home Expenses | C10: 16860 | E10: St S | F10: 36500 | N10: Baig sb
B11: US Exp | E11: ECG | N11: Bilal MR
B12: Dental Exp | C12: 200 | E12: Darex credit | F12: 22496 | H12: Total | J12: =SUM(J6:J11) -> 0 | L12: =SUM(L6:L11) -> 79000 | N12: Komal | Q12: Total | R12: =SUM(R6:R11) -> 200
B13: Store Exp | N13: Amir Shah
B14: Warda | C14: 2000 | E14: Noman Jama | F14: 15000 | H14: Store Purchases | L14: Cash | N14: Adnan | Q14: Store Exp
B15: Eisha ( kal wapis kr day gi) | C15: 10500 | H15: SK | I15: 2084 | J15: 2600 | L15: 89000 | N15: Abu Sufyan
H16: New classic | I16: 3105 | J16: 6147 | L16: 2900 | N16: Eisha | O16: 10500
B17: AC | C17: 8000 | H17: popular | I17: 3648 | J17: 5400 | N17: Shakila
H18: aman | I18: 19900 | J18: 39800 | N18: Driver K
H19: darex | I19: 22496 | J19: 47482 | N19: Abbas (Swp)
N20: Latif (Swp)
N21: NS LHV
H23: Total | I23: =SUM(I15:I22) -> 51233 | J23: =SUM(J15:J22) -> 101429 | L23: =SUM(L15:L22) -> 91900 | N23: Total | O23: =SUM(O6:O22) -> 10500 | Q23: Total | R23: =SUM(R15:R22) -> 0
H25: Clinic Expenses Details | L25: Home X | N25: Receivables | Q25: US Exp
H26: chae | J26: 280 | L26: 1060
H27: pani | J27: 240 | L27: 680
H28: baraf | J28: 300 | L28: 360
H29: SN | J29: 200 | L29: 3300
B30: Kam hisab | C30: 1000 | H30: khana | J30: 600 | L30: 200
B31: ZK | L31: 9500
B32: KH | C32: 3350 | L32: 880
B33: BP | L33: 580
B34: Total Cash Available | C34: 91900 | L34: 300
B35: Debit (Expences)Total | C35: =SUM(C6:C34) -> 186663 | E35: Credit ( Income)Total | F35: =SUM(F6:F34) -> 187946 | H35: Total | J35: =SUM(J26:J34) -> 1620 | L35: =SUM(L26:L34) -> 16860 | N35: Total | O35: =SUM(O26:O34) -> 0 | Q35: Total | R35: =SUM(R26:R34) -> 0 | T35: =SUM(T6:T34) -> 28700
B37: Cash Taken Away | C37: Daraz | E37: Notes If Any | H37: Difference | L37: Date
B38: 89000 | C38: 2900 | H38: =F35-C35 -> 1283 | L38: =TODAY() -> 46294
B39: Total Cash | C39: =SUM(B38:C38) -> 91900

Sheet 02
B5: Debit (Expences) | E5: Credit ( Income) | H5: Dispensary Purchases | L5: US Total | N5: Staff & Vendors | Q5: Dental Exp | T5: Clinic Bills
B6: Store Med Purchases | C6: 7485 | E6: Daraz Cash | F6: 2900 | H6: ES | J6: 2190 | L6: 70000 | N6: S.Naeem | O6: 1280 | R6: 200 | T6: 37500
B7: Dispensary Purchases | C7: 2190 | E7: Clinic Pt + Dispensary Inc | F7: 38850 | L7: 15000 | N7: Ammar | T7: 600
B8: Clinic Expenses | C8: 2040 | E8: LB | F8: 250 | L8: 2500 | N8: Noman | T8: 750
B9: LB Expenses | E9: US | F9: 92000 | L9: 1500 | N9: Naveed
B10: Home Expenses | C10: 17940 | E10: St S | F10: 37865 | L10: 1500 | N10: Baig sb
B11: US Exp | C11: 400 | E11: ECG | F11: 1000 | L11: 1500 | N11: Bilal MR
B12: Dental Exp | C12: 200 | H12: Total | J12: =SUM(J6:J11) -> 2190 | L12: =SUM(L6:L11) -> 92000 | N12: Komal | Q12: Total | R12: =SUM(R6:R11) -> 200
B13: Store Exp | N13: Amir Shah
H14: Store Purchases | L14: Cash | N14: Adnan | Q14: Store Exp
B15: Darex | C15: 22500 | H15: Izhar | I15: 3090 | J15: 6180 | L15: 100000 | N15: Abu Sufyan
B16: prcel ( talha + komal) | C16: 6710 | H16: orient | I16: 4395 | J16: 7450 | L16: 1700 | N16: Eisha
B17: SN | C17: 1280 | N17: Shakila
B18: Essai | C18: 200 | N18: Driver K
N19: Abbas (Swp)
N20: Latif (Swp) | O20: 200
N21: NS LHV
H23: Total | I23: =SUM(I15:I22) -> 7485 | J23: =SUM(J15:J22) -> 13630 | L23: =SUM(L15:L22) -> 101700 | N23: Total | O23: =SUM(O6:O22) -> 1480 | Q23: Total | R23: =SUM(R15:R22) -> 0
H25: Clinic Expenses Details | L25: Home X | N25: Receivables | Q25: US Exp
H26: chae | J26: 240 | L26: 1200 | Q26: Envelop | R26: 400
H27: pani baraf | J27: 500 | L27: 1000
H28: chae oper | J28: 200 | L28: 2500
J29: 500 | L29: 390
J30: 600 | L30: 6500
B31: ZK | L31: 1400
B32: KH | C32: 6500 | L32: 750
B33: BP | C33: 1500 | L33: 4200
B34: Total Cash Available | C34: 101700
B35: Debit (Expences)Total | C35: =SUM(C6:C34) -> 170645 | E35: Credit ( Income)Total | F35: =SUM(F6:F34) -> 172865 | H35: Total | J35: =SUM(J26:J34) -> 2040 | L35: =SUM(L26:L34) -> 17940 | N35: Total | O35: =SUM(O26:O34) -> 0 | Q35: Total | R35: =SUM(R26:R34) -> 400 | T35: =SUM(T6:T34) -> 38850
B37: Cash Taken Away | C37: Daraz | E37: Notes If Any | H37: Difference | L37: Date
B38: 100000 | C38: 1700 | H38: =F35-C35 -> 2220 | L38: =TODAY() -> 46294
B39: Total Cash | C39: =SUM(B38:C38) -> 101700

Sheet 03
B5: Debit (Expences) | E5: Credit ( Income) | H5: Dispensary Purchases | L5: US Total | N5: Staff & Vendors | Q5: Dental Exp | T5: Clinic Bills
B6: Store Med Purchases | C6: 39395 | E6: Daraz Cash | F6: 1600 | J6: 1670 | L6: 76000 | N6: S.Naeem | R6: 200
B7: Dispensary Purchases | C7: 1670 | E7: Clinic Pt + Dispensary Inc | F7: 25350 | L7: 4000 | N7: Ammar | T7: 25350
B8: Clinic Expenses | C8: 7280 | E8: LB | F8: 550 | N8: Noman
B9: LB Expenses | C9: 4250 | E9: US | F9: 80000 | N9: Naveed
B10: Home Expenses | C10: 134420 | E10: St S | F10: 34680 | N10: Baig sb
B11: US Exp | C11: 800 | E11: ECG | F11: 1000 | N11: Bilal MR
B12: Dental Exp | C12: 200 | H12: Total | J12: =SUM(J6:J11) -> 1670 | L12: =SUM(L6:L11) -> 80000 | N12: Komal | Q12: Total | R12: =SUM(R6:R11) -> 200
B13: Store Exp | E13: Cash from ( Dr farooq's frnd) | F13: 20000 | N13: Amir Shah
B14: warda | C14: 3800 | E14: From home for bill | F14: 100000 | H14: Store Purchases | L14: Cash | N14: Adnan | Q14: Store Exp
H15: lylpur | I15: 4855 | J15: 9250 | L15: 60000 | N15: Abu Sufyan
H16: umar | I16: 440 | J16: 1260 | L16: 2700 | N16: Eisha
H17: ayeza | I17: 2655 | J17: 8886 | N17: Shakila
H18: TF | I18: 8000 | J18: 16500 | N18: Driver K
H19: Decent | I19: 2700 | J19: 4950 | N19: Abbas (Swp)
H20: Sales link | I20: 2845 | J20: 3330 | N20: Latif (Swp)
H21: GS | I21: 17900 | J21: 38120 | N21: NS LHV
H23: Total | I23: =SUM(I15:I22) -> 39395 | J23: =SUM(J15:J22) -> 82296 | L23: =SUM(L15:L22) -> 62700 | N23: Total | O23: =SUM(O6:O22) -> 0 | Q23: Total | R23: =SUM(R15:R22) -> 0
H25: Clinic Expenses Details | L25: Home X | N25: Receivables | Q25: US Exp
H26: chae | J26: 240 | L26: 5000 | Q26: Evelop | R26: 800
H27: pani | J27: 120 | L27: 15000
H28: chae mistri SN | J28: 620 | L28: 7850
H29: baraf | J29: 300 | L29: 1400
H30: Chair repair | J30: 5200 | L30: 1050
B31: ZK | H31: khana | J31: 600 | L31: 1420
B32: KH | C32: 2500 | H32: petrol | J32: 200 | L32: 100000
B33: BP | C33: 6000 | L33: 2500
B34: Total Cash Available | C34: 62700 | L34: 200
B35: Debit (Expences)Total | C35: =SUM(C6:C34) -> 263015 | E35: Credit ( Income)Total | F35: =SUM(F6:F34) -> 263180 | H35: Total | J35: =SUM(J26:J34) -> 7280 | L35: =SUM(L26:L34) -> 134420 | N35: Total | O35: =SUM(O26:O34) -> 0 | Q35: Total | R35: =SUM(R26:R34) -> 800 | T35: =SUM(T6:T34) -> 25350
B37: Cash Taken Away | C37: Daraz | E37: Notes If Any | H37: Difference | L37: Date
B38: 60000 | C38: 2700 | H38: =F35-C35 -> 165 | L38: =TODAY() -> 46294
B39: Total Cash | C39: =SUM(B38:C38) -> 62700

Sheet 04
B5: Debit (Expences) | E5: Credit ( Income) | H5: Dispensary Purchases | L5: US Total | N5: Staff & Vendors | Q5: Dental Exp | T5: Clinic Bills
B6: Store Med Purchases | E6: Daraz Cash | F6: 2700 | N6: S.Naeem | R6: 300
B7: Dispensary Purchases | E7: Clinic Pt + Dispensary Inc | F7: 22700 | N7: Ammar
B8: Clinic Expenses | C8: 1040 | E8: LB | F8: 350 | N8: Noman
B9: LB Expenses | E9: US | F9: 71000 | N9: Naveed
B10: Home Expenses | C10: 10760 | E10: St S | F10: 29490 | N10: Baig sb
B11: US Exp | E11: ECG | N11: Bilal MR
B12: Dental Exp | C12: 300 | H12: Total | J12: =SUM(J6:J11) -> 0 | L12: =SUM(L6:L11) -> 0 | N12: Komal | Q12: Total | R12: =SUM(R6:R11) -> 300
B13: Store Exp | N13: Amir Shah
B14: SN biscuits | C14: 500 | H14: Store Purchases | L14: Cash | N14: Adnan | Q14: Store Exp
B15: Noman (adnan) | C15: 4000 | L15: 96500 | N15: Abu Sufyan
B16: Ammar | C16: 5000 | L16: 4770 | N16: Eisha
B17: AC | C17: 3000 | N17: Shakila
N18: Driver K
N19: Abbas (Swp)
N20: Latif (Swp)
N21: NS LHV
H23: Total | I23: =SUM(I15:I22) -> 0 | J23: =SUM(J15:J22) -> 0 | L23: =SUM(L15:L22) -> 101270 | N23: Total | O23: =SUM(O6:O22) -> 0 | Q23: Total | R23: =SUM(R15:R22) -> 0
H25: Clinic Expenses Details | L25: Home X | N25: Receivables | Q25: US Exp
J26: 240 | L26: 4500
J27: 180 | L27: 6260
J28: 120
J29: 500
B31: ZK
B32: KH | C32: 300
B33: BP
B34: Total Cash Available | C34: 101270
B35: Debit (Expences)Total | C35: =SUM(C6:C34) -> 126170 | E35: Credit ( Income)Total | F35: =SUM(F6:F34) -> 126240 | H35: Total | J35: =SUM(J26:J34) -> 1040 | L35: =SUM(L26:L34) -> 10760 | N35: Total | O35: =SUM(O26:O34) -> 0 | Q35: Total | R35: =SUM(R26:R34) -> 0 | T35: =SUM(T6:T34) -> 0
B37: Cash Taken Away | C37: Daraz | E37: Notes If Any | H37: Difference | L37: Date
B38: 96500 | C38: 4770 | H38: =F35-C35 -> 70 | L38: =TODAY() -> 46294
B39: Total Cash | C39: =SUM(B38:C38) -> 101270

Sheet 05
B5: Debit (Expences) | E5: Credit ( Income) | H5: Dispensary Purchases | L5: US Total | N5: Staff & Vendors | Q5: Dental Exp | T5: Clinic Bills
B6: Store Med Purchases | C6: 4379 | E6: Daraz Cash | F6: 4770 | J6: 1150 | N6: S.Naeem | O6: 1100 | R6: 200
B7: Dispensary Purchases | C7: 1150 | E7: Clinic Pt + Dispensary Inc | F7: 26900 | N7: Ammar
B8: Clinic Expenses | C8: 1800 | E8: LB | F8: 1950 | N8: Noman
B9: LB Expenses | E9: US | F9: 85300 | N9: Naveed
B10: Home Expenses | C10: 24840 | E10: St S | F10: 46479 | N10: Baig sb
B11: US Exp | E11: ECG | N11: Bilal MR
B12: Dental Exp | H12: Total | J12: =SUM(J6:J11) -> 1150 | L12: =SUM(L6:L11) -> 0 | N12: Komal | Q12: Total | R12: =SUM(R6:R11) -> 200
B13: Store Exp | N13: Amir Shah
F14: 8000 | H14: Store Purchases | L14: Cash | N14: Adnan | Q14: Store Exp
B15: tail SN | C15: 1100 | H15: ahm | I15: 1040 | J15: 3800 | L15: 132000 | N15: Abu Sufyan
H16: max | I16: 3339 | J16: 8111 | L16: 4870 | N16: Eisha
N17: Shakila
N18: Driver K
N19: Abbas (Swp)
N20: Latif (Swp)
N21: NS LHV
H23: Total | I23: =SUM(I15:I22) -> 4379 | J23: =SUM(J15:J22) -> 11911 | L23: =SUM(L15:L22) -> 136870 | N23: Total | O23: =SUM(O6:O22) -> 1100 | Q23: Total | R23: =SUM(R15:R22) -> 0
H25: Clinic Expenses Details | L25: Home X | N25: Receivables | Q25: US Exp
J26: 300
J27: 360 | L27: 24840
J28: 240
J29: 500
J30: 400
B31: ZK
B32: KH | C32: 3200
B33: BP
B34: Total Cash Available | C34: 136870
B35: Debit (Expences)Total | C35: =SUM(C6:C34) -> 173339 | E35: Credit ( Income)Total | F35: =SUM(F6:F34) -> 173399 | H35: Total | J35: =SUM(J26:J34) -> 1800 | L35: =SUM(L26:L34) -> 24840 | N35: Total | O35: =SUM(O26:O34) -> 0 | Q35: Total | R35: =SUM(R26:R34) -> 0 | T35: =SUM(T6:T34) -> 0
B37: Cash Taken Away | C37: Daraz | E37: Notes If Any | H37: Difference | L37: Date
B38: 132000 | C38: 4870 | H38: =F35-C35 -> 60 | L38: =TODAY() -> 46294
B39: Total Cash | C39: =SUM(B38:C38) -> 136870

Sheet 06
B5: Debit (Expences) | E5: Credit ( Income) | H5: Dispensary Purchases | L5: US Total | N5: Staff & Vendors | Q5: Dental Exp | T5: Clinic Bills
B6: Store Med Purchases | C6: 860 | E6: Daraz Cash | F6: 4870 | H6: Es | J6: 1650 | L6: 94000 | N6: S.Naeem | R6: 200 | T6: 30850
B7: Dispensary Purchases | C7: 15710 | E7: Clinic Pt + Dispensary Inc | F7: 32750 | H7: ES | J7: 5660 | L7: 26300 | N7: Ammar | T7: 850
B8: Clinic Expenses | C8: 1780 | E8: LB | F8: 1250 | J8: 8400 | L8: 1000 | N8: Noman | T8: 1050
B9: LB Expenses | E9: US | F9: 121300 | N9: Naveed
B10: Home Expenses | C10: 18548 | E10: St S | F10: 33458 | N10: Baig sb
B11: US Exp | C11: 1000 | E11: ECG | N11: Bilal MR
B12: Dental Exp | C12: 200 | H12: Total | J12: =SUM(J6:J11) -> 15710 | L12: =SUM(L6:L11) -> 121300 | N12: Komal | Q12: Total | R12: =SUM(R6:R11) -> 200
B13: Store Exp | N13: Amir Shah
B14: Bilal | C14: 20000 | H14: Store Purchases | L14: Cash | N14: Adnan | Q14: Store Exp
H15: Talha | I15: 860 | J15: 1000 | L15: 103000 | N15: Abu Sufyan
L16: 15000 | N16: Eisha
L17: 1310 | N17: Shakila
N18: Driver K
N19: Abbas (Swp)
N20: Latif (Swp)
N21: NS LHV
H23: Total | I23: =SUM(I15:I22) -> 860 | J23: =SUM(J15:J22) -> 1000 | L23: =SUM(L15:L22) -> 119310 | N23: Total | O23: =SUM(O6:O22) -> 0 | Q23: Total | R23: =SUM(R15:R22) -> 0
H25: Clinic Expenses Details | L25: Home X | N25: Receivables | Q25: US Exp
H26: pani | J26: 120 | L26: 338 | Q26: US Exp | R26: 1000
H27: chae | J27: 280 | L27: 6150
H28: chae | J28: 280 | L28: 970
H29: baraf | J29: 150 | L29: 2100
H30: khana | J30: 600 | L30: 1520
B31: ZK | C31: 2200 | H31: pani bottle | J31: 350 | L31: 1770
B32: KH | C32: 6000 | L32: 700
B33: BP | C33: 8000 | L33: 5000
B34: Total Cash Available | C34: 119310
B35: Debit (Expences)Total | C35: =SUM(C6:C34) -> 193608 | E35: Credit ( Income)Total | F35: =SUM(F6:F34) -> 193628 | H35: Total | J35: =SUM(J26:J34) -> 1780 | L35: =SUM(L26:L34) -> 18548 | N35: Total | O35: =SUM(O26:O34) -> 0 | Q35: Total | R35: =SUM(R26:R34) -> 1000 | T35: =SUM(T6:T34) -> 32750
B37: Cash Taken Away | C37: Daraz | E37: Notes If Any | H37: Difference | L37: Date
B38: 103000 | C38: 16310 | H38: =F35-C35 -> 20 | L38: =TODAY() -> 46294
B39: Total Cash | C39: =SUM(B38:C38) -> 119310

Sheet 07
B5: Debit (Expences) | E5: Credit ( Income) | H5: Dispensary Purchases | L5: US Total | N5: Staff & Vendors | Q5: Dental Exp | T5: Clinic Bills
B6: Store Med Purchases | C6: 24208 | E6: Daraz Cash | F6: 16300 | H6: umar | J6: 905 | L6: 74000 | N6: S.Naeem | Q6: khana | R6: 200 | T6: 23150
B7: Dispensary Purchases | C7: 905 | E7: Clinic Pt + Dispensary Inc | F7: 23150 | L7: 6000 | N7: Ammar | Q7: saman | R7: 650
B8: Clinic Expenses | C8: 2770 | E8: LB | F8: 1150 | N8: Noman | Q8: mask | R8: 950
B9: LB Expenses | E9: US | F9: 80000 | N9: Naveed
B10: Home Expenses | C10: 10300 | E10: St S | F10: 30883 | N10: Baig sb
B11: US Exp | E11: ECG | N11: Bilal MR
B12: Dental Exp | C12: 1800 | H12: Total | J12: =SUM(J6:J11) -> 905 | L12: =SUM(L6:L11) -> 80000 | N12: Komal | Q12: Total | R12: =SUM(R6:R11) -> 1800
B13: Store Exp | N13: Amir Shah
B14: A/C | C14: 10000 | H14: Store Purchases | L14: Cash | N14: Adnan | Q14: Store Exp
B15: Bilal | C15: 15000 | H15: Mushtaq | I15: 4989 | J15: 7802 | L15: 78000 | N15: Abu Sufyan
E16: bilal | F16: 11900 | H16: umar | I16: 586 | J16: 2110 | L16: 710 | N16: Eisha
H17: SA | I17: 2349 | J17: 3750 | L17: 15000 | N17: Shakila
H18: Almustafa | I18: 2228 | J18: 4500 | N18: Driver K
H19: Azeem | I19: 661 | J19: 1100 | N19: Abbas (Swp)
H20: Serine | I20: 1495 | J20: 1750 | N20: Latif (Swp)
H21: bilal | I21: 11900 | J21: 18830 | N21: NS LHV
H23: Total | I23: =SUM(I15:I22) -> 24208 | J23: =SUM(J15:J22) -> 39842 | L23: =SUM(L15:L22) -> 93710 | N23: Total | O23: =SUM(O6:O22) -> 0 | Q23: Total | R23: =SUM(R15:R22) -> 0
H25: Clinic Expenses Details | L25: Home X | N25: Receivables | Q25: US Exp
H26: builty | J26: 700 | L26: 5000
H27: khana | J27: 600 | L27: 1250
H28: chae | J28: 280 | L28: 1300
H29: chae | J29: 70 | L29: 1050
H30: chae | J30: 120 | L30: 1100
B31: ZK | C31: 200 | H31: baraf pani | J31: 500 | L31: 600
B32: KH | C32: 4500 | H32: petrol | J32: 500
B33: BP
B34: Total Cash Available | C34: 93710
B35: Debit (Expences)Total | C35: =SUM(C6:C34) -> 163393 | E35: Credit ( Income)Total | F35: =SUM(F6:F34) -> 163383 | H35: Total | J35: =SUM(J26:J34) -> 2770 | L35: =SUM(L26:L34) -> 10300 | N35: Total | O35: =SUM(O26:O34) -> 0 | Q35: Total | R35: =SUM(R26:R34) -> 0 | T35: =SUM(T6:T34) -> 23150
B37: Cash Taken Away | C37: Daraz | E37: Notes If Any | H37: Difference | L37: Date
B38: 78000 | C38: 15700 | H38: =F35-C35 -> -10 | L38: =TODAY() -> 46294
B39: Total Cash | C39: =SUM(B38:C38) -> 93700

Sheet 08
B5: Debit (Expences) | E5: Credit ( Income) | H5: Dispensary Purchases | L5: US Total | N5: Staff & Vendors | Q5: Dental Exp | T5: Clinic Bills
B6: Store Med Purchases | C6: 6914 | E6: Daraz Cash | F6: 15700 | H6: ES | J6: 1700 | L6: 79000 | N6: S.Naeem | O6: 3500 | Q6: khana | R6: 200 | T6: 28800
B7: Dispensary Purchases | C7: 1700 | E7: Clinic Pt + Dispensary Inc | F7: 30100 | L7: 8400 | N7: Ammar | Q7: Saman | R7: 500 | T7: 650
B8: Clinic Expenses | C8: 13210 | E8: LB | F8: 750 | L8: 4500 | N8: Noman | T8: 650
B9: LB Expenses | E9: US | F9: 91900 | N9: Naveed
B10: Home Expenses | C10: 15910 | E10: St S | F10: 30601 | N10: Baig sb
B11: US Exp | E11: ECG | N11: Bilal MR
B12: Dental Exp | C12: 700 | H12: Total | J12: =SUM(J6:J11) -> 1700 | L12: =SUM(L6:L11) -> 91900 | N12: Komal | Q12: Total | R12: =SUM(R6:R11) -> 700
B13: Store Exp | N13: Amir Shah
H14: Store Purchases | L14: Cash | N14: Adnan | Q14: Store Exp
B15: SN saman etc | C15: 3500 | H15: Fair | I15: 960 | J15: 3000 | L15: 100000 | N15: Abu Sufyan
H16: Popular | I16: 2601 | J16: 3900 | L16: 13000 | N16: Eisha
H17: New classic | I17: 3353 | J17: 6375 | L17: 10000 | N17: Shakila
L18: 3420 | N18: Driver K
N19: Abbas (Swp)
N20: Latif (Swp)
N21: NS LHV
H23: Total | I23: =SUM(I15:I22) -> 6914 | J23: =SUM(J15:J22) -> 13275 | L23: =SUM(L15:L22) -> 126420 | N23: Total | O23: =SUM(O6:O22) -> 3500 | Q23: Total | R23: =SUM(R15:R22) -> 0
H25: Clinic Expenses Details | L25: Home X | N25: Receivables | Q25: US Exp
H26: chae | J26: 250 | L26: 2220
H27: chae | J27: 120 | L27: 1500
H28: admi court | J28: 500 | L28: 7200
H29: hameed sweet | J29: 1000 | L29: 950
H30: banch repair | J30: 10000 | L30: 1440
B31: ZK | H31: khana | J31: 600 | L31: 1000
B32: KH | H32: pani baraf | J32: 500 | L32: 1100
B33: BP | H33: SN chae raat | J33: 240 | L33: 500
B34: Total Cash Available | C34: 126420
B35: Debit (Expences)Total | C35: =SUM(C6:C34) -> 168354 | E35: Credit ( Income)Total | F35: =SUM(F6:F34) -> 169051 | H35: Total | J35: =SUM(J26:J34) -> 13210 | L35: =SUM(L26:L34) -> 15910 | N35: Total | O35: =SUM(O26:O34) -> 0 | Q35: Total | R35: =SUM(R26:R34) -> 0 | T35: =SUM(T6:T34) -> 30100
B37: Cash Taken Away | C37: Daraz | E37: Notes If Any | H37: Difference | L37: Date
B38: 113000 | C38: 13420 | H38: =F35-C35 -> 697 | L38: =TODAY() -> 46294
B39: Total Cash | C39: =SUM(B38:C38) -> 126420

Sheet 09
B5: Debit (Expences) | E5: Credit ( Income) | H5: Dispensary Purchases | L5: US Total | N5: Staff & Vendors | Q5: Dental Exp | T5: Clinic Bills
B6: Store Med Purchases | C6: 8709 | E6: Daraz Cash | F6: 13400 | H6: Asif | J6: 23567 | L6: 69000 | N6: S.Naeem | R6: 200 | T6: 26950
B7: Dispensary Purchases | C7: 69923 | E7: Clinic Pt + Dispensary Inc | F7: 26950 | J7: 34974 | L7: 3000 | N7: Ammar
B8: Clinic Expenses | C8: 3540 | E8: LB | F8: 850 | H8: Asif | J8: 11382 | N8: Noman
B9: LB Expenses | E9: US | F9: 72000 | N9: Naveed
B10: Home Expenses | C10: 10300 | E10: St S | F10: 33299 | N10: Baig sb
B11: US Exp | E11: ECG | N11: Bilal MR
B12: Dental Exp | C12: 200 | H12: Total | J12: =SUM(J6:J11) -> 69923 | L12: =SUM(L6:L11) -> 72000 | N12: Komal | Q12: Total | R12: =SUM(R6:R11) -> 200
B13: Store Exp | N13: Amir Shah
H14: Store Purchases | L14: Cash | N14: Adnan | Q14: Store Exp
B15: Car oil chage service | C15: 10000 | E15: Disp med fsd total | F15: 69923 | H15: izhar | I15: 2475 | J15: 6543 | L15: 100000 | N15: Abu Sufyan
H16: Orient | I16: 4525 | J16: 7730 | L16: 10000 | N16: Eisha
H17: SM | I17: 1709 | J17: 2000 | L17: 1400 | N17: Shakila
L18: 1500 | N18: Driver K
N19: Abbas (Swp)
N20: Latif (Swp)
N21: NS LHV
H23: Total | I23: =SUM(I15:I22) -> 8709 | J23: =SUM(J15:J22) -> 16273 | L23: =SUM(L15:L22) -> 112900 | N23: Total | O23: =SUM(O6:O22) -> 0 | Q23: Total | R23: =SUM(R15:R22) -> 0
H25: Clinic Expenses Details | L25: Home X | N25: Receivables | Q25: US Exp
H26: chae | J26: 250 | L26: 500
H27: pani | J27: 240 | L27: 300
H28: baraf | J28: 450 | L28: 2000
H29: petrol | J29: 500 | L29: 6000
H30: wakeel and print | J30: 1400 | L30: 1500
B31: ZK | H31: khana | J31: 600
B32: KH | C32: 1000 | H32: abaas kharcha | J32: 100
B33: BP
B34: Total Cash Available | C34: 112900
B35: Debit (Expences)Total | C35: =SUM(C6:C34) -> 216572 | E35: Credit ( Income)Total | F35: =SUM(F6:F34) -> 216422 | H35: Total | J35: =SUM(J26:J34) -> 3540 | L35: =SUM(L26:L34) -> 10300 | N35: Total | O35: =SUM(O26:O34) -> 0 | Q35: Total | R35: =SUM(R26:R34) -> 0 | T35: =SUM(T6:T34) -> 26950
B37: Cash Taken Away | C37: Daraz | E37: Notes If Any | H37: Difference | L37: Date
B38: 100000 | C38: 12900 | H38: =F35-C35 -> -150 | L38: =TODAY() -> 46294
B39: Total Cash | C39: =SUM(B38:C38) -> 112900

Sheet 10
B5: Debit (Expences) | E5: Credit ( Income) | H5: Dispensary Purchases | L5: US Total | N5: Staff & Vendors | Q5: Dental Exp | T5: Clinic Bills
B6: Store Med Purchases | C6: 4890 | E6: Daraz Cash | F6: 12900 | H6: ES | J6: 2630 | L6: 71000 | N6: S.Naeem | R6: 200 | T6: 36000
B7: Dispensary Purchases | C7: 2630 | E7: Clinic Pt + Dispensary Inc | F7: 42450 | L7: 5800 | N7: Ammar | T7: 1000
B8: Clinic Expenses | C8: 1670 | E8: LB | F8: 700 | L8: 2300 | N8: Noman | T8: 650
B9: LB Expenses | C9: 1150 | E9: US | F9: 81100 | L9: 2000 | N9: Naveed | T9: 850
B10: Home Expenses | C10: 20130 | E10: St S | F10: 45410 | N10: Baig sb | T10: 600
B11: US Exp | E11: ECG | N11: Bilal MR | T11: 850
B12: Dental Exp | C12: 200 | H12: Total | J12: =SUM(J6:J11) -> 2630 | L12: =SUM(L6:L11) -> 81100 | N12: Komal | Q12: Total | R12: =SUM(R6:R11) -> 200 | T12: 650
B13: Store Exp | N13: Amir Shah | T13: 500
H14: Store Purchases | L14: Cash | N14: Adnan | O14: 10000 | Q14: Store Exp | T14: 600
B15: Shakila | C15: 3750 | H15: Decent | I15: 1400 | J15: 2500 | L15: 72000 | N15: Abu Sufyan | T15: 750
B16: Saira | C16: 25000 | H16: Ayeza | I16: 3490 | J16: 10700 | L16: 10000 | N16: Eisha
B17: cash ammar | C17: 25000 | L17: 1300 | N17: Shakila | O17: 3750
B18: Adnan | C18: 10000 | N18: Driver K
B19: Abbas | C19: 1500 | N19: Abbas (Swp)
N20: Latif (Swp)
N21: NS LHV
H23: Total | I23: =SUM(I15:I22) -> 4890 | J23: =SUM(J15:J22) -> 13200 | L23: =SUM(L15:L22) -> 83300 | N23: Total | O23: =SUM(O6:O22) -> 13750 | Q23: Total | R23: =SUM(R15:R22) -> 0
H25: Clinic Expenses Details | L25: Home X | N25: Receivables | Q25: US Exp
J26: 120 | L26: 670
J27: 150 | L27: 1000
J28: 150 | L28: 11000
H29: jharu | J29: 300 | L29: 3000
J30: 600 | L30: 960
B31: ZK | J31: 250 | L31: 1500
B32: KH | C32: 2900 | H32: chokidar | J32: 100 | L32: 1000
B33: BP | L33: 1000
B34: Total Cash Available | C34: 83300
B35: Debit (Expences)Total | C35: =SUM(C6:C34) -> 182120 | E35: Credit ( Income)Total | F35: =SUM(F6:F34) -> 182560 | H35: Total | J35: =SUM(J26:J34) -> 1670 | L35: =SUM(L26:L34) -> 20130 | N35: Total | O35: =SUM(O26:O34) -> 0 | Q35: Total | R35: =SUM(R26:R34) -> 0 | T35: =SUM(T6:T34) -> 42450
B37: Cash Taken Away | C37: Daraz | E37: Notes If Any | H37: Difference | L37: Date
B38: 72000 | C38: 11300 | H38: =F35-C35 -> 440 | L38: =TODAY() -> 46294
B39: Total Cash | C39: =SUM(B38:C38) -> 83300

Sheet 11
B5: Debit (Expences) | E5: Credit ( Income) | H5: Dispensary Purchases | L5: US Total | N5: Staff & Vendors | Q5: Dental Exp | T5: Clinic Bills
B6: Store Med Purchases | E6: Daraz Cash | F6: 11000 | L6: 55000 | N6: S.Naeem | R6: 100 | T6: 24150
B7: Dispensary Purchases | E7: Clinic Pt + Dispensary Inc | F7: 28600 | L7: 8800 | N7: Ammar | T7: 750
B8: Clinic Expenses | C8: 52230 | E8: LB | F8: 1250 | L8: 1000 | N8: Noman | T8: 3050
B9: LB Expenses | E9: US | F9: 66300 | L9: 1500 | N9: Naveed | T9: 650
B10: Home Expenses | C10: 15100 | E10: St S | F10: 42160 | N10: Baig sb
B11: US Exp | E11: ECG | N11: Bilal MR
B12: Dental Exp | C12: 100 | H12: Total | J12: =SUM(J6:J11) -> 0 | L12: =SUM(L6:L11) -> 66300 | N12: Komal | Q12: Total | R12: =SUM(R6:R11) -> 100
B13: Store Exp | N13: Amir Shah
B14: Bakhi | C14: 8000 | H14: Store Purchases | L14: Cash | N14: Adnan | Q14: Store Exp
L15: 50000 | N15: Abu Sufyan
B16: SN pani | C16: 960 | L16: 18000 | N16: Eisha
B17: Abbas clear for aug | C17: 4500 | N17: Shakila
B18: Noor fatima udhar | C18: 750 | N18: Driver K
N19: Abbas (Swp) | O19: 4500
N20: Latif (Swp)
N21: NS LHV
H23: Total | I23: =SUM(I15:I22) -> 0 | J23: =SUM(J15:J22) -> 0 | L23: =SUM(L15:L22) -> 68000 | N23: Total | O23: =SUM(O6:O22) -> 4500 | Q23: Total | R23: =SUM(R15:R22) -> 0
H25: Clinic Expenses Details | L25: Home X | N25: Receivables | Q25: US Exp
H26: Farnail | J26: 350 | L26: 13630 | N26: noor Fatima | O26: 750
H27: khana | J27: 600 | L27: 1470
H28: chae | J28: 640
H29: chae | J29: 140
H30: FBR kharcha | J30: 50000
B31: ZK | C31: 200 | H31: pani baraf | J31: 500
B32: KH
B33: BP
B34: Total Cash Available | C34: 68000
B35: Debit (Expences)Total | C35: =SUM(C6:C34) -> 149840 | E35: Credit ( Income)Total | F35: =SUM(F6:F34) -> 149310 | H35: Total | J35: =SUM(J26:J34) -> 52230 | L35: =SUM(L26:L34) -> 15100 | N35: Total | O35: =SUM(O26:O34) -> 750 | Q35: Total | R35: =SUM(R26:R34) -> 0 | T35: =SUM(T6:T34) -> 28600
B37: Cash Taken Away | C37: Daraz | E37: Notes If Any | H37: Difference | L37: Date
B38: 50000 | C38: 18000 | H38: =F35-C35 -> -530 | L38: =TODAY() -> 46294
B39: Total Cash | C39: =SUM(B38:C38) -> 68000

Sheet 12
B5: Debit (Expences) | E5: Credit ( Income) | H5: Dispensary Purchases | L5: US Total | N5: Staff & Vendors | Q5: Dental Exp | T5: Clinic Bills
B6: Store Med Purchases | C6: 34469 | E6: Daraz Cash | F6: 18000 | H6: ES | J6: 2430 | L6: 87000 | N6: S.Naeem | R6: 200 | T6: 35150
B7: Dispensary Purchases | C7: 4880 | E7: Clinic Pt + Dispensary Inc | F7: 51100 | H7: syringes | J7: 800 | L7: 10000 | N7: Ammar | R7: 500 | T7: 2000
B8: Clinic Expenses | C8: 8530 | E8: LB | F8: 1050 | H8: drips | J8: 1650 | L8: 1500 | N8: Noman | T8: 10000
B9: LB Expenses | E9: US | F9: 98500 | N9: Naveed | T9: 1650
B10: Home Expenses | C10: 15000 | E10: St S | F10: 36834 | N10: Baig sb | T10: 500
B11: US Exp | E11: ECG | N11: Bilal MR | T11: 1300
B12: Dental Exp | C12: 700 | H12: Total | J12: =SUM(J6:J11) -> 4880 | L12: =SUM(L6:L11) -> 98500 | N12: Komal | Q12: Total | R12: =SUM(R6:R11) -> 700 | T12: 500
B13: Store Exp | N13: Amir Shah
H14: Store Purchases | L14: Cash | N14: Adnan | Q14: Store Exp
B15: warda | C15: 2000 | H15: MR | I15: 5119 | J15: 9500 | L15: 80000 | N15: Abu Sufyan
B16: Adnan | C16: 250 | H16: Madix | I16: 1655 | J16: 2050 | L16: 10000 | N16: Eisha
B17: Bilal | C17: 15000 | H17: GS | I17: 27695 | J17: 71200 | L17: 100 | N17: Shakila
B18: kmaiti | C18: 30000 | N18: Driver K
N19: Abbas (Swp)
N20: Latif (Swp)
N21: NS LHV
H23: Total | I23: =SUM(I15:I22) -> 34469 | J23: =SUM(J15:J22) -> 82750 | L23: =SUM(L15:L22) -> 90100 | N23: Total | O23: =SUM(O6:O22) -> 0 | Q23: Total | R23: =SUM(R15:R22) -> 0
H25: Clinic Expenses Details | L25: Home X | N25: Receivables | Q25: US Exp
J26: 140 | L26: 1430
J27: 370 | L27: 750
J28: 120 | L28: 6000
E29: . | J29: 300 | L29: 2000
J30: 500 | L30: 1000
B31: ZK | C31: 200 | H31: rikhsaw kiraya | J31: 300 | L31: 3820
B32: KH | C32: 3500 | H32: saman | J32: 700
B33: BP | H33: mistri | J33: 5500
B34: Total Cash Available | C34: 90100 | H34: khana | J34: 600
B35: Debit (Expences)Total | C35: =SUM(C6:C34) -> 204629 | E35: Credit ( Income)Total | F35: =SUM(F6:F34) -> 205484 | H35: Total | J35: =SUM(J26:J34) -> 8530 | L35: =SUM(L26:L34) -> 15000 | N35: Total | O35: =SUM(O26:O34) -> 0 | Q35: Total | R35: =SUM(R26:R34) -> 0 | T35: =SUM(T6:T34) -> 51100
B37: Cash Taken Away | C37: Daraz | E37: Notes If Any | H37: Difference | L37: Date
B38: 80000 | C38: 10000 | H38: =F35-C35 -> 855 | L38: =TODAY() -> 46294
B39: Total Cash | C39: =SUM(B38:C38) -> 90000

Sheet 13
B5: Debit (Expences) | E5: Credit ( Income) | H5: Dispensary Purchases | L5: US Total | N5: Staff & Vendors | Q5: Dental Exp | T5: Clinic Bills
B6: Store Med Purchases | C6: 2780 | E6: Daraz Cash | F6: 10000 | J6: 3600 | L6: 107000 | N6: S.Naeem | R6: 200 | T6: 30000
B7: Dispensary Purchases | C7: 11670 | E7: Clinic Pt + Dispensary Inc | F7: 31800 | J7: 2100 | L7: 4800 | N7: Ammar | T7: 1300
B8: Clinic Expenses | C8: 7720 | E8: LB | F8: 1350 | J8: 1500 | N8: Noman | T8: 500
B9: LB Expenses | E9: US | F9: 111800 | J9: 950 | N9: Naveed
